<?xml version="1.0"?>
<robot xmlns:xacro="http://ros.org/wiki/xacro" name="two-engines">
  <!-- Macro for inserting an engine with its propeller. -->
  <xacro:macro name="engine" params="prefix position:='0 0 0' orientation:='0 0 0'">
    <link name="${prefix}_engine_link">
      <collision name="${prefix}_engine_vertical_axis_collision">
        <origin xyz="0 0 0" rpy="0 0 0" />
        <geometry>
          <box size="0.001 0.001 0.001" />
        </geometry>
      </collision>
      <collision name="${prefix}_engine_rear_end_collision">
        <origin xyz="0 0 0" rpy="0 0 0" />
        <geometry>
          <box size="0.001 0.001 0.001" />
        </geometry>
      </collision>
      <inertial>
        <mass value="0.1"/>
        <inertia ixx="0.889245" ixy="0.0" ixz="0.0" iyy="0.911125" iyz="0.0" izz="0.078125"/>
      </inertial>
    </link>

    <link name="${prefix}_propeller_link">
      <collision name="${prefix}_propeller_collision">
        <origin xyz="0 0 0" rpy="0 0 0" />
        <geometry>
            <mesh filename="package://heron_sim/models/heron/actuators/thruster_description/mesh/prop.dae" scale="1 1 1" />
        </geometry>
      </collision>
      <inertial>
        <mass value="0.1"/>
        <inertia ixx="0.008545" ixy="0.0" ixz="0.0" iyy="0.008545" iyz="0.0" izz="0.0144"/>
      </inertial>
      <visual>
        <geometry>
          <mesh filename="package://heron_sim/models/heron/actuators/thruster_description/mesh/prop.dae" scale="1 1 1" />
        </geometry>
      </visual>
    </link>

    <joint name="${prefix}_chasis_engine_joint" type="fixed">
      <origin xyz="${position}" rpy="${orientation}"/>
      <parent link="nav_link"/>
      <child link="${prefix}_engine_link"/>
    </joint>

    <joint name="${prefix}_engine_propeller_joint" type="continuous">
      <axis rpy="0 0 0" xyz="1 0 0"/>
      <parent link="${prefix}_engine_link"/>
      <child link="${prefix}_propeller_link"/>
      <origin rpy="0 0 0" xyz="0 0 0"/>
      <limit effort="100" velocity="100" />
      <dynamics friction="0.05" damping="0.05" />
    </joint>
  </xacro:macro>
</robot>
